Workbook

Sheet Electronics & Life
A1: Category | B1: Test Number | C1: Test Method | D1: Engineer | E1: Technician | F1: 893 | G1: 990 | H1: 923 | I1: 946-A | J1: 922 | K1: 873 | L1: 913 | M1: 990b | N1: 505-N* | O1: 953 | P1: 990a | Q1: 980 | R1: 308-N* | S1: 505-M | T1: 505-0* | U1: 995 | V1: 308-L | W1: 924 | X1: 1008 | Y1: 982 | Z1: 982a | AA1: 978 | AB1: 921a | AC1: 1014 | AD1: H1 | AE1: H2 | AF1: 982b | AG1: 1005
A2: ELectronics & Motor | B2: TM-0000464 | C2: DTM 721 Machine Current Draw & Power Consumption | D2: Khym Suwan Sobejana | E2: Arvin | F2: 4 | G2: 3 | H2: 2 | I2: 0 | J2: 12 | K2: 0 | L2: 0 | M2: 0 | N2: 32 | O2: 12 | P2: 12 | Q2: 3 | R2: 4 | S2: 2 | T2: 2 | U2: 0 | V2: 0 | W2: 0 | X2: 5 | Y2: 2 | Z2: 32 | AA2: 2 | AB2: 26 | AC2: 6 | AD2: 26 | AE2: 26 | AF2: 25 | AG2: 5
A3: ELectronics & Motor | B3: TM-002704 | C3: PCBA Concentrated Saline Stress Test | D3: Khym Suwan Sobejana | E3: Arvin | F3: 10 | G3: 5 | H3: 12 | I3: 0 | J3: 0 | K3: 6 | L3: 5 | M3: 12 | N3: 23 | O3: 32 | P3: 0 | Q3: 0 | R3: 2 | S3: 0 | T3: 14 | U3: 5 | V3: 12 | W3: 2 | X3: 24 | Y3: 7 | Z3: 1 | AA3: 3 | AB3: 0 | AC3: 0 | AD3: 12 | AE3: 2 | AF3: 12 | AG3: 0
A4: ELectronics & Motor | B4: TM-002832 | C4: US N332 ALCI Test Method ALCI/PRCD test method | D4: Khym Suwan Sobejana | E4: Arvin | F4: 0 | G4: 4 | H4: 3 | I4: 0 | J4: 11 | K4: 1 | L4: 4 | M4: 3 | N4: 2 | O4: 2 | P4: 4 | Q4: 0 | R4: 19 | S4: 23 | T4: 0 | U4: 4 | V4: 3 | W4: 43 | X4: 23 | Y4: 22 | Z4: 22 | AA4: 1 | AB4: 1 | AC4: 0 | AD4: 32 | AE4: 21 | AF4: 44 | AG4: 0
A5: ELectronics & Motor | B5: TM-003589 | C5: Moisture & Liquid Ingress for Personal Care | D5: Khym Suwan Sobejana | E5: Mico | F5: 0 | G5: 5 | H5: 2 | I5: 0 | J5: 11 | K5: 1 | L5: 5 | M5: 2 | N5: 2 | O5: 0 | P5: 1 | Q5: 11 | R5: 11 | S5: 2 | T5: 0 | U5: 5 | V5: 2 | W5: 12 | X5: 23 | Y5: 2 | Z5: 1 | AA5: 5 | AB5: 0 | AC5: 2 | AD5: 43 | AE5: 2 | AF5: 32 | AG5: 12
A6: ELectronics & Motor | B6: TM-003733 | C6: Contaminants & Dust Ingress | D6: Khym Suwan Sobejana | E6: Arvin | F6: 0 | G6: 23 | H6: 12 | I6: 0 | J6: 7 | K6: 17 | L6: 23 | M6: 12 | N6: 2 | O6: 12 | P6: 2 | Q6: 0 | R6: 34 | S6: 2 | T6: 3 | U6: 23 | V6: 12 | W6: 11 | X6: 1 | Y6: 0 | Z6: 2 | AA6: 24 | AB6: 6 | AC6: 0 | AD6: 17 | AE6: 23 | AF6: 17 | AG6: 23
A7: ELectronics & Motor | B7: TM-100030 | C7: DTM923-Standby Power Consumption Measurement | D7: Khym Suwan Sobejana | E7: Arvin | F7: 1 | G7: 7 | H7: 32 | I7: 12 | J7: 23 | K7: 12 | L7: 7 | M7: 32 | N7: 21 | O7: 44 | P7: 22 | Q7: 0 | R7: 1 | S7: 2 | T7: 2 | U7: 7 | V7: 32 | W7: 2 | X7: 7 | Y7: 0 | Z7: 43 | AA7: 23 | AB7: 0 | AC7: 11 | AD7: 12 | AE7: 7 | AF7: 12 | AG7: 7
A8: ELectronics & Motor | B8: TM-100251 | C8: Water Ingress - Salt Mist Test | D8: Nina Rich Medina | E8: Arvin | F8: 23 | G8: 7 | H8: 43 | I8: 2 | J8: 23 | K8: 2 | L8: 7 | M8: 43 | N8: 2 | O8: 32 | P8: 2 | Q8: 24 | R8: 0 | S8: 21 | T8: 12 | U8: 7 | V8: 43 | W8: 7 | X8: 2 | Y8: 0 | Z8: 12 | AA8: 23 | AB8: 5 | AC8: 21 | AD8: 2 | AE8: 7 | AF8: 2 | AG8: 7
A9: ELectronics & Motor | B9: TM-100590 | C9: Performance Life Test | D9: Khym Suwan Sobejana | E9: Arvin | F9: 2 | G9: 7 | H9: 2 | I9: 32 | J9: 20 | K9: 1 | L9: 7 | M9: 2 | N9: 15 | O9: 2 | P9: 43 | Q9: 23 | R9: 0 | S9: 2 | T9: 32 | U9: 7 | V9: 2 | W9: 6 | X9: 1 | Y9: 4 | Z9: 11 | AA9: 1 | AB9: 2 | AC9: 2 | AD9: 7 | AE9: 32 | AF9: 0 | AG9: 2
A10: ELectronics & Motor | B10: TM-200124 | C10: Single Mode Life Test | D10: Khym Suwan Sobejana | E10: Arvin | F10: 4 | G10: 6 | H10: 1 | I10: 22 | J10: 31 | K10: 6 | L10: 6 | M10: 1 | N10: 0 | O10: 0 | P10: 12 | Q10: 23 | R10: 0 | S10: 15 | T10: 0 | U10: 6 | V10: 1 | W10: 1 | X10: 2 | Y10: 5 | Z10: 2 | AA10: 7 | AB10: 1 | AC10: 1 | AD10: 2 | AE10: 0 | AF10: 0 | AG10: 23
A11: ELectronics & Motor | B11: TM-200338 | C11: Product Air Outlet Leakage Current Test | D11: Khym Suwan Sobejana | E11: Arvin | F11: 5 | G11: 1 | H11: 2 | I11: 12 | J11: 6 | K11: 6 | L11: 1 | M11: 2 | N11: 0 | O11: 0 | P11: 11 | Q11: 1 | R11: 0 | S11: 4 | T11: 3 | U11: 2 | V11: 2 | W11: 23 | X11: 2 | Y11: 23 | Z11: 2 | AA11: 32 | AB11: 2 | AC11: 26 | AD11: 0 | AE11: 0 | AF11: 2 | AG11: 7
A12: ELectronics & Motor | B12: TM-200407 | C12: X605G ToF Temperature Rise Test | D12: Khym Suwan Sobejana | E12: Arvin | F12: 14 | G12: 23 | H12: 2 | I12: 10 | J12: 5 | K12: 6 | L12: 23 | M12: 2 | N12: 34 | O12: 2 | P12: 2 | Q12: 7 | R12: 0 | S12: 5 | T12: 2 | U12: 2 | V12: 2 | W12: 0 | X12: 0 | Y12: 7 | Z12: 0 | AA12: 0 | AB12: 0 | AC12: 43 | AD12: 23 | AE12: 0 | AF12: 0 | AG12: 7

Sheet Performance
A1: Category | B1: Test Number | C1: Test Method | D1: Engineer | E1: Technician | F1: 893 | G1: 990 | H1: 923 | I1: 946-A | J1: 922 | K1: 873 | L1: 913 | M1: 990b | N1: 505-N* | O1: 953 | P1: 990a | Q1: 980 | R1: 308-N* | S1: 505-M | T1: 505-0* | U1: 995 | V1: 308-L | W1: 924 | X1: 1008 | Y1: 982 | Z1: 982a | AA1: 978 | AB1: 921a | AC1: 1014 | AD1: H1 | AE1: H2 | AF1: 982b | AG1: 1005
A2: Performance 1 | B2: TM-0000777 | C2: DTM 912 Primary Air Flow Rate Test | D2: Jomer Laparan | E2: JL | F2: 4 | G2: 3 | H2: 2 | I2: 0 | J2: 12 | K2: 0 | L2: 0 | M2: 0 | N2: 32 | O2: 12 | P2: 12 | Q2: 3 | R2: 4 | S2: 2 | T2: 2 | U2: 0 | V2: 0 | W2: 0 | X2: 5 | Y2: 2 | Z2: 32 | AA2: 2 | AB2: 26 | AC2: 6 | AD2: 26 | AE2: 26 | AF2: 25 | AG2: 5
A3: Performance 1 | B3: TM-002088 | C3: Airflow Performance of a Hair Drying Appliance | D3: Mark Jason Presingular | E3: JL | F3: 10 | G3: 5 | H3: 12 | I3: 0 | J3: 0 | K3: 6 | L3: 5 | M3: 12 | N3: 23 | O3: 32 | P3: 0 | Q3: 0 | R3: 2 | S3: 0 | T3: 14 | U3: 5 | V3: 12 | W3: 2 | X3: 24 | Y3: 7 | Z3: 1 | AA3: 3 | AB3: 0 | AC3: 0 | AD3: 12 | AE3: 2 | AF3: 12 | AG3: 0
A4: Performance 1 | B4: TM-002118 | C4: Hairdryer evaporation performance (IEC Dry rate) | D4: Mark Jason Presingular | E4: JL | F4: 0 | G4: 4 | H4: 3 | I4: 0 | J4: 11 | K4: 1 | L4: 4 | M4: 3 | N4: 2 | O4: 2 | P4: 4 | Q4: 0 | R4: 19 | S4: 23 | T4: 0 | U4: 4 | V4: 3 | W4: 43 | X4: 23 | Y4: 22 | Z4: 22 | AA4: 1 | AB4: 1 | AC4: 0 | AD4: 32 | AE4: 21 | AF4: 44 | AG4: 0
A5: Performance 1 | B5: TM-002523 | C5: X332 Surface Temperature Mapping | D5: Mark Jason Presingular | E5: Yael | F5: 0 | G5: 5 | H5: 2 | I5: 0 | J5: 11 | K5: 1 | L5: 5 | M5: 2 | N5: 2 | O5: 0 | P5: 1 | Q5: 11 | R5: 11 | S5: 2 | T5: 0 | U5: 5 | V5: 2 | W5: 12 | X5: 23 | Y5: 2 | Z5: 1 | AA5: 5 | AB5: 0 | AC5: 2 | AD5: 43 | AE5: 2 | AF5: 32 | AG5: 12
A6: Performance 1 | B6: TM-002725 | C6: Hair Styling Product - Retention Test | D6: Mark Jason Presingular | E6: Yael | F6: 0 | G6: 23 | H6: 12 | I6: 0 | J6: 7 | K6: 17 | L6: 23 | M6: 12 | N6: 2 | O6: 12 | P6: 2 | Q6: 0 | R6: 34 | S6: 2 | T6: 3 | U6: 23 | V6: 12 | W6: 11 | X6: 1 | Y6: 0 | Z6: 2 | AA6: 24 | AB6: 6 | AC6: 0 | AD6: 17 | AE6: 23 | AF6: 17 | AG6: 23
A7: Performance 1 | B7: TM-002888 | C7: (UL) Outlet air temperature of a hair drying appliance | D7: Mark Jason Presingular | E7: JL | F7: 1 | G7: 7 | H7: 32 | I7: 12 | J7: 23 | K7: 12 | L7: 7 | M7: 32 | N7: 21 | O7: 44 | P7: 22 | Q7: 0 | R7: 1 | S7: 2 | T7: 2 | U7: 7 | V7: 32 | W7: 2 | X7: 7 | Y7: 0 | Z7: 43 | AA7: 23 | AB7: 0 | AC7: 11 | AD7: 12 | AE7: 7 | AF7: 12 | AG7: 7
A8: Performance 1 | B8: TM-002948 | C8: General Measurements | D8: Mark Jason Presingular | E8: JL | F8: 23 | G8: 7 | H8: 43 | I8: 2 | J8: 23 | K8: 2 | L8: 7 | M8: 43 | N8: 2 | O8: 32 | P8: 2 | Q8: 24 | R8: 0 | S8: 21 | T8: 12 | U8: 7 | V8: 43 | W8: 7 | X8: 2 | Y8: 0 | Z8: 12 | AA8: 23 | AB8: 5 | AC8: 21 | AD8: 2 | AE8: 7 | AF8: 2 | AG8: 7
A9: Performance 1 | B9: TM-003012 | C9: Wrap Performance Test Method | D9: Brian Brazal | E9: JL | F9: 2 | G9: 7 | H9: 2 | I9: 32 | J9: 20 | K9: 1 | L9: 7 | M9: 2 | N9: 15 | O9: 2 | P9: 43 | Q9: 23 | R9: 0 | S9: 2 | T9: 32 | U9: 7 | V9: 2 | W9: 6 | X9: 1 | Y9: 4 | Z9: 11 | AA9: 1 | AB9: 2 | AC9: 2 | AD9: 7 | AE9: 32 | AF9: 0 | AG9: 2
A10: Performance 1 | B10: TM-003034 | C10: Hair Binding Method | D10: Mark Jason Presingular | E10: JL | F10: 4 | G10: 6 | H10: 1 | I10: 22 | J10: 31 | K10: 6 | L10: 6 | M10: 1 | N10: 0 | O10: 0 | P10: 12 | Q10: 23 | R10: 0 | S10: 15 | T10: 0 | U10: 6 | V10: 1 | W10: 1 | X10: 2 | Y10: 5 | Z10: 2 | AA10: 7 | AB10: 1 | AC10: 1 | AD10: 2 | AE10: 0 | AF10: 0 | AG10: 23
A11: Performance 1 | B11: TM-003128 | C11: Tress Imaging | D11: Mark Jason Presingular | E11: Yael | F11: 5 | G11: 1 | H11: 2 | I11: 12 | J11: 6 | K11: 6 | L11: 1 | M11: 2 | N11: 0 | O11: 0 | P11: 11 | Q11: 1 | R11: 0 | S11: 4 | T11: 3 | U11: 2 | V11: 2 | W11: 23 | X11: 2 | Y11: 23 | Z11: 2 | AA11: 32 | AB11: 2 | AC11: 26 | AD11: 0 | AE11: 0 | AF11: 2 | AG11: 7
A12: Performance 1 | B12: TM-003156 | C12: Hot Air Brush Performance Test | D12: Mark Jason Presingular | E12: JL | F12: 14 | G12: 23 | H12: 2 | I12: 10 | J12: 5 | K12: 6 | L12: 23 | M12: 2 | N12: 34 | O12: 2 | P12: 2 | Q12: 7 | R12: 0 | S12: 5 | T12: 2 | U12: 2 | V12: 2 | W12: 0 | X12: 0 | Y12: 7 | Z12: 0 | AA12: 0 | AB12: 0 | AC12: 43 | AD12: 23 | AE12: 0 | AF12: 0 | AG12: 7
A13: Performance 1 | B13: TM-003159 | C13: Damp Hair Tress Preparation Method | D13: Mark Jason Presingular | E13: JL | F13: 4 | G13: 3 | H13: 2 | I13: 0 | J13: 12 | K13: 0 | L13: 0 | M13: 0 | N13: 32 | O13: 12 | P13: 12 | Q13: 3 | R13: 4 | S13: 2 | T13: 2 | U13: 0 | V13: 0 | W13: 0 | X13: 5 | Y13: 2 | Z13: 32 | AA13: 2 | AB13: 26 | AC13: 6 | AD13: 26 | AE13: 26 | AF13: 25 | AG13: 5
... A77: Performance 2 | B77: TM-200409 | C77: X605G ToF Temperature Protect Test | D77: Mark Jason Presingular | E77: JL | F77: 2 | G77: 7 | H77: 2 | I77: 32 | J77: 20 | K77: 1 | L77: 7 | M77: 2 | N77: 15 | O77: 2 | P77: 43 | Q77: 23 | R77: 0 | S77: 2 | T77: 32 | U77: 7 | V77: 2 | W77: 6 | X77: 1 | Y77: 4 | Z77: 11 | AA77: 1 | AB77: 2 | AC77: 2 | AD77: 7 | AE77: 32 | AF77: 0 | AG77: 2

Sheet Sheet6
A1: DTM 912 Primary Air Flow Rate Test
A2: Airflow Performance of a Hair Drying Appliance
A3: Hairdryer evaporation performance (IEC Dry rate)
A4: X332 Surface Temperature Mapping
A5: Hair Styling Product - Retention Test
A6: (UL) Outlet air temperature of a hair drying appliance
A7: General Measurements
A8: Wrap Performance Test Method
A9: Hair Binding Method
A10: Tress Imaging
A11: Hot Air Brush Performance Test
A12: Damp Hair Tress Preparation Method
... A38: X605G ToF Temperature Protect Test

Sheet TM Number
A1: TM-0000777
A2: TM-002088
A3: TM-002118
A4: TM-002523
A5: TM-002725
A6: TM-002888
A7: TM-002948
A8: TM-003012
A9: TM-003034
A10: TM-003128
A11: TM-003156
A12: TM-003159
... A38: TM-200409

Sheet Sheet4
A1: DTM023 Switch Life Test
A2: DTM040 Packaging Drop Test
A3: DTM 533 Removable Parts, clips and catches
A4: DTM 028 Cable Oscillation Test
A5: DTM 560 Cord/Plug Oscillation Test
A6: DTM 712 - Materials - Chemical Resistance - Surface Application
A7: DTM 728 Plug Pin Bending Test
A8: DTM 808 Free Loading Shipment Simulation Test
A9: DTM815 Physical Resistance Test
A10: DTM 902 Tampo Durability Test
A11: DTM 900 Cordset Pull Out Test
A12: DTM 908 Pull Test
... A25: Cosmetic Durability

Sheet Sheet3
A1: TM-0000025
A2: TM-0000028
A3: TM-0000426
A4: TM-0000427
A5: TM-0000448
A6: TM-0000458
A7: TM-0000463
A8: TM-0000523
A9: TM-0000539
A10: TM-0000618
A11: TM-0000674
A12: TM-0000693
... A25: TM-200181

Sheet Sheet1
A1: TM-0000464
A2: TM-002704
A3: TM-002832
A4: TM-003589
A5: TM-003733
A6: TM-100030
A7: TM-100251
A8: TM-100590
A9: TM-200124
A10: TM-200338
A11: TM-200407

Sheet Sheet2
A1: DTM 721 Machine Current Draw & Power Consumption
A2: PCBA Concentrated Saline Stress Test
A3: US N332 ALCI Test Method ALCI/PRCD test method
A4: Moisture & Liquid Ingress for Personal Care
A5: Contaminants & Dust Ingress
A6: DTM923-Standby Power Consumption Measurement
A7: Water Ingress - Salt Mist Test
A8: Performance Life Test
A9: Single Mode Life Test
A10: Product Air Outlet Leakage Current Test
A11: X605G ToF Temperature Rise Test

Sheet Robustness
A1: Category | B1: Test Number | C1: Test Method | D1: Engineer | E1: Technician | F1: 893 | G1: 990 | H1: 923 | I1: 946-A | J1: 922 | K1: 873 | L1: 913 | M1: 990b | N1: 505-N* | O1: 953 | P1: 990a | Q1: 980 | R1: 308-N* | S1: 505-M | T1: 505-0* | U1: 995 | V1: 308-L | W1: 924 | X1: 1008 | Y1: 982 | Z1: 982a | AA1: 978 | AB1: 921a | AC1: 1014 | AD1: H1 | AE1: H2 | AF1: 982b | AG1: 1005
A2: Robustness | B2: TM-0000025 | C2: DTM023 Switch Life Test | D2: Mark Jason Presingular | E2: Omar | F2: 4 | G2: 3 | H2: 2 | I2: 0 | J2: 12 | K2: 0 | L2: 0 | M2: 0 | N2: 32 | O2: 12 | P2: 12 | Q2: 3 | R2: 4 | S2: 2 | T2: 2 | U2: 0 | V2: 0 | W2: 0 | X2: 5 | Y2: 2 | Z2: 32 | AA2: 2 | AB2: 26 | AC2: 6 | AD2: 26 | AE2: 26 | AF2: 25 | AG2: 5
A3: Robustness | B3: TM-0000028 | C3: DTM040 Packaging Drop Test | D3: Khym Suwan Sobejana | E3: Omar | F3: 10 | G3: 5 | H3: 12 | I3: 0 | J3: 0 | K3: 6 | L3: 5 | M3: 12 | N3: 23 | O3: 32 | P3: 0 | Q3: 0 | R3: 2 | S3: 0 | T3: 14 | U3: 5 | V3: 12 | W3: 2 | X3: 24 | Y3: 7 | Z3: 1 | AA3: 3 | AB3: 0 | AC3: 0 | AD3: 12 | AE3: 2 | AF3: 12 | AG3: 0
A4: Robustness | B4: TM-0000426 | C4: DTM 533 Removable Parts, clips and catches | D4: Khym Suwan Sobejana | E4: Omar | F4: 0 | G4: 4 | H4: 3 | I4: 0 | J4: 11 | K4: 1 | L4: 4 | M4: 3 | N4: 2 | O4: 2 | P4: 4 | Q4: 0 | R4: 19 | S4: 23 | T4: 0 | U4: 4 | V4: 3 | W4: 43 | X4: 23 | Y4: 22 | Z4: 22 | AA4: 1 | AB4: 1 | AC4: 0 | AD4: 32 | AE4: 21 | AF4: 44 | AG4: 0
A5: Robustness | B5: TM-0000427 | C5: DTM 028 Cable Oscillation Test | D5: Jomer Laparan | E5: Mico | F5: 0 | G5: 5 | H5: 2 | I5: 0 | J5: 11 | K5: 1 | L5: 5 | M5: 2 | N5: 2 | O5: 0 | P5: 1 | Q5: 11 | R5: 11 | S5: 2 | T5: 0 | U5: 5 | V5: 2 | W5: 12 | X5: 23 | Y5: 2 | Z5: 1 | AA5: 5 | AB5: 0 | AC5: 2 | AD5: 43 | AE5: 2 | AF5: 32 | AG5: 12
A6: Robustness | B6: TM-0000448 | C6: DTM 560 Cord/Plug Oscillation Test | D6: Nina Rich Medina | E6: Mico | F6: 0 | G6: 23 | H6: 12 | I6: 0 | J6: 7 | K6: 17 | L6: 23 | M6: 12 | N6: 2 | O6: 12 | P6: 2 | Q6: 0 | R6: 34 | S6: 2 | T6: 3 | U6: 23 | V6: 12 | W6: 11 | X6: 1 | Y6: 0 | Z6: 2 | AA6: 24 | AB6: 6 | AC6: 0 | AD6: 17 | AE6: 23 | AF6: 17 | AG6: 23
A7: Robustness | B7: TM-0000458 | C7: DTM 712 - Materials - Chemical Resistance - Surface Application | D7: Khym Suwan Sobejana | E7: JL | F7: 1 | G7: 7 | H7: 32 | I7: 12 | J7: 23 | K7: 12 | L7: 7 | M7: 32 | N7: 21 | O7: 44 | P7: 22 | Q7: 0 | R7: 1 | S7: 2 | T7: 2 | U7: 7 | V7: 32 | W7: 2 | X7: 7 | Y7: 0 | Z7: 43 | AA7: 23 | AB7: 0 | AC7: 11 | AD7: 12 | AE7: 7 | AF7: 12 | AG7: 7
A8: Robustness | B8: TM-0000463 | C8: DTM 728 Plug Pin Bending Test | D8: Khym Suwan Sobejana | E8: JL | F8: 23 | G8: 7 | H8: 43 | I8: 2 | J8: 23 | K8: 2 | L8: 7 | M8: 43 | N8: 2 | O8: 32 | P8: 2 | Q8: 24 | R8: 0 | S8: 21 | T8: 12 | U8: 7 | V8: 43 | W8: 7 | X8: 2 | Y8: 0 | Z8: 12 | AA8: 23 | AB8: 5 | AC8: 21 | AD8: 2 | AE8: 7 | AF8: 2 | AG8: 7
A9: Robustness | B9: TM-0000523 | C9: DTM 808 Free Loading Shipment Simulation Test | D9: Mark Jason Presingular | E9: Leoben | F9: 2 | G9: 7 | H9: 2 | I9: 32 | J9: 20 | K9: 1 | L9: 7 | M9: 2 | N9: 15 | O9: 2 | P9: 43 | Q9: 23 | R9: 0 | S9: 2 | T9: 32 | U9: 7 | V9: 2 | W9: 6 | X9: 1 | Y9: 4 | Z9: 11 | AA9: 1 | AB9: 2 | AC9: 2 | AD9: 7 | AE9: 32 | AF9: 0 | AG9: 2
A10: Robustness | B10: TM-0000539 | C10: DTM815 Physical Resistance Test | D10: Mark Jason Presingular | E10: JL | F10: 4 | G10: 6 | H10: 1 | I10: 22 | J10: 31 | K10: 6 | L10: 6 | M10: 1 | N10: 0 | O10: 0 | P10: 12 | Q10: 23 | R10: 0 | S10: 15 | T10: 0 | U10: 6 | V10: 1 | W10: 1 | X10: 2 | Y10: 5 | Z10: 2 | AA10: 7 | AB10: 1 | AC10: 1 | AD10: 2 | AE10: 0 | AF10: 0 | AG10: 23
A11: Robustness | B11: TM-0000618 | C11: DTM 902 Tampo Durability Test | D11: Mark Jason Presingular | E11: JL | F11: 5 | G11: 1 | H11: 2 | I11: 12 | J11: 6 | K11: 6 | L11: 1 | M11: 2 | N11: 0 | O11: 0 | P11: 11 | Q11: 1 | R11: 0 | S11: 4 | T11: 3 | U11: 2 | V11: 2 | W11: 23 | X11: 2 | Y11: 23 | Z11: 2 | AA11: 32 | AB11: 2 | AC11: 26 | AD11: 0 | AE11: 0 | AF11: 2 | AG11: 7
A12: Robustness | B12: TM-0000674 | C12: DTM 900 Cordset Pull Out Test | D12: Mark Jason Presingular | E12: Mico | F12: 14 | G12: 23 | H12: 2 | I12: 10 | J12: 5 | K12: 6 | L12: 23 | M12: 2 | N12: 34 | O12: 2 | P12: 2 | Q12: 7 | R12: 0 | S12: 5 | T12: 2 | U12: 2 | V12: 2 | W12: 0 | X12: 0 | Y12: 7 | Z12: 0 | AA12: 0 | AB12: 0 | AC12: 43 | AD12: 23 | AE12: 0 | AF12: 0 | AG12: 7
A13: Robustness | B13: TM-0000693 | C13: DTM 908 Pull Test | D13: Mark Jason Presingular | E13: Mico | F13: 4 | G13: 3 | H13: 2 | I13: 0 | J13: 12 | K13: 0 | L13: 0 | M13: 0 | N13: 32 | O13: 12 | P13: 12 | Q13: 3 | R13: 4 | S13: 2 | T13: 2 | U13: 0 | V13: 0 | W13: 0 | X13: 5 | Y13: 2 | Z13: 32 | AA13: 2 | AB13: 26 | AC13: 6 | AD13: 26 | AE13: 26 | AF13: 25 | AG13: 5
... A25: Robustness | B25: TM-200130 | C25: Accelerated Usage Life Test | D25: Khym Suwan Sobejana | E25: Leoben | F25: 10 | G25: 5 | H25: 12 | I25: 0 | J25: 0 | K25: 6 | L25: 5 | M25: 12 | N25: 23 | O25: 32 | P25: 0 | Q25: 0 | R25: 2 | S25: 0 | T25: 14 | U25: 5 | V25: 12 | W25: 2 | X25: 24 | Y25: 7 | Z25: 1 | AA25: 3 | AB25: 0 | AC25: 0 | AD25: 12 | AE25: 2 | AF25: 12 | AG25: 0
A26: Robustness | B26: TM-200181 | C26: Cosmetic Durability | D26: Khym Suwan Sobejana | F26: 0 | G26: 4 | H26: 3 | I26: 0 | J26: 11 | K26: 1 | L26: 4 | M26: 3 | N26: 2 | O26: 2 | P26: 4 | Q26: 0 | R26: 19 | S26: 23 | T26: 0 | U26: 4 | V26: 3 | W26: 43 | X26: 23 | Y26: 22 | Z26: 22 | AA26: 1 | AB26: 1 | AC26: 0 | AD26: 32 | AE26: 21 | AF26: 44 | AG26: 0
A27: UI | B27: TM-0000025 | C27: DTM023 Switch Life Test | D27: Jomer Laparan | E27: Mico | F27: 4 | G27: 3 | H27: 2 | I27: 0 | J27: 12 | K27: 0 | L27: 0 | M27: 0 | N27: 32 | O27: 12 | P27: 12 | Q27: 3 | R27: 4 | S27: 2 | T27: 2 | U27: 0 | V27: 0 | W27: 0 | X27: 5 | Y27: 2 | Z27: 32 | AA27: 2 | AB27: 26 | AC27: 6 | AD27: 26 | AE27: 26 | AF27: 25 | AG27: 5
A28: UI | B28: TM-0000028 | C28: DTM040 Packaging Drop Test | D28: Mark Jason Presingular | E28: Mico | F28: 10 | G28: 5 | H28: 12 | I28: 0 | J28: 0 | K28: 6 | L28: 5 | M28: 12 | N28: 23 | O28: 32 | P28: 0 | Q28: 0 | R28: 2 | S28: 0 | T28: 14 | U28: 5 | V28: 12 | W28: 2 | X28: 24 | Y28: 7 | Z28: 1 | AA28: 3 | AB28: 0 | AC28: 0 | AD28: 12 | AE28: 2 | AF28: 12 | AG28: 0
A29: UI | B29: TM-0000426 | C29: DTM 533 Removable Parts, clips and catches | D29: Mark Jason Presingular | E29: Mico | F29: 0 | G29: 4 | H29: 3 | I29: 0 | J29: 11 | K29: 1 | L29: 4 | M29: 3 | N29: 2 | O29: 2 | P29: 4 | Q29: 0 | R29: 19 | S29: 23 | T29: 0 | U29: 4 | V29: 3 | W29: 43 | X29: 23 | Y29: 22 | Z29: 22 | AA29: 1 | AB29: 1 | AC29: 0 | AD29: 32 | AE29: 21 | AF29: 44 | AG29: 0
A30: UI | B30: TM-0000427 | C30: DTM 028 Cable Oscillation Test | D30: Mark Jason Presingular | E30: JL | F30: 0 | G30: 5 | H30: 2 | I30: 0 | J30: 11 | K30: 1 | L30: 5 | M30: 2 | N30: 2 | O30: 0 | P30: 1 | Q30: 11 | R30: 11 | S30: 2 | T30: 0 | U30: 5 | V30: 2 | W30: 12 | X30: 23 | Y30: 2 | Z30: 1 | AA30: 5 | AB30: 0 | AC30: 2 | AD30: 43 | AE30: 2 | AF30: 32 | AG30: 12
A31: UI | B31: TM-0000448 | C31: DTM 560 Cord/Plug Oscillation Test | D31: Mark Jason Presingular | E31: JL | F31: 0 | G31: 23 | H31: 12 | I31: 0 | J31: 7 | K31: 17 | L31: 23 | M31: 12 | N31: 2 | O31: 12 | P31: 2 | Q31: 0 | R31: 34 | S31: 2 | T31: 3 | U31: 23 | V31: 12 | W31: 11 | X31: 1 | Y31: 0 | Z31: 2 | AA31: 24 | AB31: 6 | AC31: 0 | AD31: 17 | AE31: 23 | AF31: 17 | AG31: 23
A32: UI | B32: TM-0000458 | C32: DTM 712 - Materials - Chemical Resistance - Surface Application | D32: Mark Jason Presingular | E32: Omar | F32: 1 | G32: 7 | H32: 32 | I32: 12 | J32: 23 | K32: 12 | L32: 7 | M32: 32 | N32: 21 | O32: 44 | P32: 22 | Q32: 0 | R32: 1 | S32: 2 | T32: 2 | U32: 7 | V32: 32 | W32: 2 | X32: 7 | Y32: 0 | Z32: 43 | AA32: 23 | AB32: 0 | AC32: 11 | AD32: 12 | AE32: 7 | AF32: 12 | AG32: 7
A33: UI | B33: TM-0000463 | C33: DTM 728 Plug Pin Bending Test | D33: Mark Jason Presingular | E33: Mico | F33: 23 | G33: 7 | H33: 43 | I33: 2 | J33: 23 | K33: 2 | L33: 7 | M33: 43 | N33: 2 | O33: 32 | P33: 2 | Q33: 24 | R33: 0 | S33: 21 | T33: 12 | U33: 7 | V33: 43 | W33: 7 | X33: 2 | Y33: 0 | Z33: 12 | AA33: 23 | AB33: 5 | AC33: 21 | AD33: 2 | AE33: 7 | AF33: 2 | AG33: 7
A34: UI | B34: TM-0000523 | C34: DTM 808 Free Loading Shipment Simulation Test | D34: Mark Jason Presingular | E34: Mico | F34: 2 | G34: 7 | H34: 2 | I34: 32 | J34: 20 | K34: 1 | L34: 7 | M34: 2 | N34: 15 | O34: 2 | P34: 43 | Q34: 23 | R34: 0 | S34: 2 | T34: 32 | U34: 7 | V34: 2 | W34: 6 | X34: 1 | Y34: 4 | Z34: 11 | AA34: 1 | AB34: 2 | AC34: 2 | AD34: 7 | AE34: 32 | AF34: 0 | AG34: 2
A35: UI | B35: TM-0000539 | C35: DTM815 Physical Resistance Test | D35: Mark Jason Presingular | E35: Leoben | F35: 4 | G35: 6 | H35: 1 | I35: 22 | J35: 31 | K35: 6 | L35: 6 | M35: 1 | N35: 0 | O35: 0 | P35: 12 | Q35: 23 | R35: 0 | S35: 15 | T35: 0 | U35: 6 | V35: 1 | W35: 1 | X35: 2 | Y35: 5 | Z35: 2 | AA35: 7 | AB35: 1 | AC35: 1 | AD35: 2 | AE35: 0 | AF35: 0 | AG35: 23
A36: UI | B36: TM-0000618 | C36: DTM 902 Tampo Durability Test | D36: Mark Jason Presingular | E36: Leoben | F36: 5 | G36: 1 | H36: 2 | I36: 12 | J36: 6 | K36: 6 | L36: 1 | M36: 2 | N36: 0 | O36: 0 | P36: 11 | Q36: 1 | R36: 0 | S36: 4 | T36: 3 | U36: 2 | V36: 2 | W36: 23 | X36: 2 | Y36: 23 | Z36: 2 | AA36: 32 | AB36: 2 | AC36: 26 | AD36: 0 | AE36: 0 | AF36: 2 | AG36: 7
A37: UI | B37: TM-0000674 | C37: DTM 900 Cordset Pull Out Test | D37: Jomer Laparan | E37: Leoben | F37: 14 | G37: 23 | H37: 2 | I37: 10 | J37: 5 | K37: 6 | L37: 23 | M37: 2 | N37: 34 | O37: 2 | P37: 2 | Q37: 7 | R37: 0 | S37: 5 | T37: 2 | U37: 2 | V37: 2 | W37: 0 | X37: 0 | Y37: 7 | Z37: 0 | AA37: 0 | AB37: 0 | AC37: 43 | AD37: 23 | AE37: 0 | AF37: 0 | AG37: 7
A38: UI | B38: TM-0000693 | C38: DTM 908 Pull Test | D38: Jomer Laparan | E38: Leoben | F38: 4 | G38: 3 | H38: 2 | I38: 0 | J38: 12 | K38: 0 | L38: 0 | M38: 0 | N38: 32 | O38: 12 | P38: 12 | Q38: 3 | R38: 4 | S38: 2 | T38: 2 | U38: 0 | V38: 0 | W38: 0 | X38: 5 | Y38: 2 | Z38: 32 | AA38: 2 | AB38: 26 | AC38: 6 | AD38: 26 | AE38: 26 | AF38: 25 | AG38: 5
... A50: UI | B50: TM-200130 | C50: Accelerated Usage Life Test | D50: Jomer Laparan | E50: JL | F50: 10 | G50: 5 | H50: 12 | I50: 0 | J50: 0 | K50: 6 | L50: 5 | M50: 12 | N50: 23 | O50: 32 | P50: 0 | Q50: 0 | R50: 2 | S50: 0 | T50: 14 | U50: 5 | V50: 12 | W50: 2 | X50: 24 | Y50: 7 | Z50: 1 | AA50: 3 | AB50: 0 | AC50: 0 | AD50: 12 | AE50: 2 | AF50: 12 | AG50: 0
A51: UI | B51: TM-200181 | C51: Cosmetic Durability | D51: Jomer Laparan | F51: 0 | G51: 4 | H51: 3 | I51: 0 | J51: 11 | K51: 1 | L51: 4 | M51: 3 | N51: 2 | O51: 2 | P51: 4 | Q51: 0 | R51: 19 | S51: 23 | T51: 0 | U51: 4 | V51: 3 | W51: 43 | X51: 23 | Y51: 22 | Z51: 22 | AA51: 1 | AB51: 1 | AC51: 0 | AD51: 32 | AE51: 21 | AF51: 44 | AG51: 0

Sheet TestMethods
A1: User Course Test (Personal Care)
A2: Drop Test Attachment Level
A3: Drop Test Clause 1A
A4: Drop Test Clause 1B
A5: Drop Test Clause 2
A6: DTM 712 - Materials - Chemical Resistance - Surface Application
A7: Accelerated Usage Life Test
A8: DTM 533 Removable Parts, clips and catches
A9: DTM 902 Tampo Durability Test
A10: DTM815 Physical Resistance Test
A11: DTM 900 Cordset Pull Out Test
A12: Personal Long Hair Ingress
... A101: Leakage Current for Components and Sub-Assembly

Sheet Laboratories

Sheet Sheet5

Sheet Sheet7
A1: Jomer Laparan
A2: Khym Suwan Sobejana
A3: Mark Jason Presingular
A4: Nina Rich Medina
A5: Brian Brazal

Sheet Sheet8
A1: Leona
A2: Yael
A3: Mico
A4: Omar
A5: JL
A6: Arvin
A7: Leoben
A8: Joseph
A9: Gemma
A10: Bernard G.
A11: Rex

Sheet TestNumber
A1: TM-0000025
A2: TM-0000028
A3: TM-0000186
A4: TM-0000372
A5: TM-0000392
A6: TM-0000426
A7: TM-0000427
A8: TM-0000448
A9: TM-0000458
A10: TM-0000463
A11: TM-0000464
A12: TM-0000516
... A102: TM-200409

Sheet Master_Data
A1: Laboratory | B1: Test Number | C1: Test | D1: Engineer | E1: Technician | F1: 893 | G1: 990 | H1: 923 | I1: 946A | J1: 922 | K1: 308M | L1: 873 | M1: 913 | N1: 953 | O1: 942 | P1: 921A | Q1: 990A | R1: 980 | S1: 1027 | T1: 505N | U1: 1008 | V1: 982 | W1: 982A | X1: 1014 | Y1: 1022 | Z1: 1023 | AA1: 982B | AB1: 1005 | AC1: LX1391 | AD1: LX1392 | AE1: LX1274
A2: User Interaction | B2: TM-002643 | C2: User Course Test (Personal Care) | D2: Khym Suwan Sobejana | E2: Leona | F2: 9 | G2: 0 | H2: 6 | I2: 0 | J2: 12 | K2: 0 | L2: 0 | M2: 6 | N2: 0 | O2: 32 | P2: 12 | Q2: 12 | R2: 3 | S2: 4 | T2: 2 | U2: 2 | V2: 0 | W2: 0 | X2: 0 | Y2: 5 | Z2: 2 | AA2: 32 | AB2: 2 | AC2: 26 | AD2: 6 | AE2: 26
A3: User Interaction | B3: TM-003440 | C3: Drop Test Attachment Level | D3: Mark Jason Presingular | E3: Leona | F3: 10 | G3: 5 | H3: 12 | I3: 0 | J3: 0 | K3: 6 | L3: 6 | M3: 5 | N3: 12 | O3: 23 | P3: 32 | Q3: 0 | R3: 0 | S3: 2 | T3: 0 | U3: 14 | V3: 5 | W3: 12 | X3: 2 | Y3: 24 | Z3: 7 | AA3: 1 | AB3: 3 | AC3: 0 | AD3: 0 | AE3: 12
A4: User Interaction | B4: TM-003440 | C4: Drop Test Clause 1A | D4: Mark Jason Presingular | E4: Leona | F4: 0 | G4: 4 | H4: 3 | I4: 0 | J4: 11 | K4: 1 | L4: 1 | M4: 4 | N4: 3 | O4: 2 | P4: 2 | Q4: 4 | R4: 0 | S4: 19 | T4: 23 | U4: 0 | V4: 4 | W4: 3 | X4: 43 | Y4: 23 | Z4: 22 | AA4: 22 | AB4: 1 | AC4: 1 | AD4: 0 | AE4: 32
A5: User Interaction | B5: TM-003440 | C5: Drop Test Clause 1B | D5: Jomer Laparan | E5: Leona | F5: 0 | G5: 5 | H5: 2 | I5: 0 | J5: 11 | K5: 1 | L5: 1 | M5: 5 | N5: 2 | O5: 2 | P5: 0 | Q5: 1 | R5: 11 | S5: 11 | T5: 2 | U5: 0 | V5: 5 | W5: 2 | X5: 12 | Y5: 23 | Z5: 2 | AA5: 1 | AB5: 5 | AC5: 0 | AD5: 2 | AE5: 43
A6: User Interaction | B6: TM-003440 | C6: Drop Test Clause 2 | D6: Nina Rich Medina | E6: Leona | F6: 0 | G6: 23 | H6: 12 | I6: 0 | J6: 7 | K6: 17 | L6: 17 | M6: 23 | N6: 12 | O6: 2 | P6: 12 | Q6: 2 | R6: 0 | S6: 34 | T6: 2 | U6: 3 | V6: 23 | W6: 12 | X6: 11 | Y6: 1 | Z6: 0 | AA6: 2 | AB6: 24 | AC6: 6 | AD6: 0 | AE6: 17
A7: User Interaction | B7: TM-0000458 | C7: DTM 712 - Materials - Chemical Resistance - Surface Application | D7: Mark Jason Presingular | E7: Leona | F7: 1 | G7: 7 | H7: 32 | I7: 12 | J7: 23 | K7: 12 | L7: 12 | M7: 7 | N7: 32 | O7: 21 | P7: 44 | Q7: 22 | R7: 0 | S7: 1 | T7: 2 | U7: 2 | V7: 7 | W7: 32 | X7: 2 | Y7: 7 | Z7: 0 | AA7: 43 | AB7: 23 | AC7: 0 | AD7: 11 | AE7: 12
A8: User Interaction | B8: TM-200130 | C8: Accelerated Usage Life Test | D8: Khym Suwan Sobejana | E8: Leona | F8: 23 | G8: 7 | H8: 43 | I8: 2 | J8: 23 | K8: 2 | L8: 2 | M8: 7 | N8: 43 | O8: 2 | P8: 32 | Q8: 2 | R8: 24 | S8: 0 | T8: 21 | U8: 12 | V8: 7 | W8: 43 | X8: 7 | Y8: 2 | Z8: 0 | AA8: 12 | AB8: 23 | AC8: 5 | AD8: 21 | AE8: 2
A9: User Interaction | B9: TM-0000426 | C9: DTM 533 Removable Parts, clips and catches | D9: Mark Jason Presingular | E9: Yael | F9: 2 | G9: 7 | H9: 2 | I9: 32 | J9: 20 | K9: 1 | L9: 1 | M9: 7 | N9: 2 | O9: 15 | P9: 2 | Q9: 43 | R9: 23 | S9: 0 | T9: 2 | U9: 32 | V9: 7 | W9: 2 | X9: 6 | Y9: 1 | Z9: 4 | AA9: 11 | AB9: 1 | AC9: 2 | AD9: 2 | AE9: 7
A10: User Interaction | B10: TM-0000618 | C10: DTM 902 Tampo Durability Test | D10: Mark Jason Presingular | E10: Leona | F10: 4 | G10: 6 | H10: 1 | I10: 22 | J10: 31 | K10: 6 | L10: 6 | M10: 6 | N10: 1 | O10: 0 | P10: 0 | Q10: 12 | R10: 23 | S10: 0 | T10: 15 | U10: 0 | V10: 6 | W10: 1 | X10: 1 | Y10: 2 | Z10: 5 | AA10: 2 | AB10: 7 | AC10: 1 | AD10: 1 | AE10: 2
A11: User Interaction | B11: TM-0000539 | C11: DTM815 Physical Resistance Test | D11: Mark Jason Presingular | E11: Leona | F11: 5 | G11: 1 | H11: 2 | I11: 12 | J11: 6 | K11: 6 | L11: 6 | M11: 1 | N11: 2 | O11: 0 | P11: 0 | Q11: 11 | R11: 1 | S11: 0 | T11: 4 | U11: 3 | V11: 2 | W11: 2 | X11: 23 | Y11: 2 | Z11: 23 | AA11: 2 | AB11: 32 | AC11: 2 | AD11: 26 | AE11: 0
A12: User Interaction | B12: TM-0000674 | C12: DTM 900 Cordset Pull Out Test | D12: Khym Suwan Sobejana | E12: Yael | F12: 14 | G12: 23 | H12: 2 | I12: 10 | J12: 5 | K12: 6 | L12: 6 | M12: 23 | N12: 2 | O12: 34 | P12: 2 | Q12: 2 | R12: 7 | S12: 0 | T12: 5 | U12: 2 | V12: 2 | W12: 2 | X12: 0 | Y12: 0 | Z12: 7 | AA12: 0 | AB12: 0 | AC12: 0 | AD12: 43 | AE12: 23
A13: User Interaction | B13: TM-003706 | C13: Personal Long Hair Ingress | D13: Khym Suwan Sobejana | E13: Leona | F13: 4 | G13: 3 | H13: 2 | I13: 0 | J13: 12 | K13: 0 | L13: 0 | M13: 0 | N13: 0 | O13: 32 | P13: 12 | Q13: 12 | R13: 3 | S13: 4 | T13: 2 | U13: 2 | V13: 0 | W13: 0 | X13: 0 | Y13: 5 | Z13: 2 | AA13: 32 | AB13: 2 | AC13: 26 | AD13: 6 | AE13: 26
... A102: Electronics | B102: TM-200378 | C102: Leakage Current for Components and Sub-Assembly | D102: Jomer Laparan | E102: Arvin | F102: 4 | G102: 3 | H102: 2 | I102: 0 | J102: 12 | K102: 0 | L102: 0 | M102: 0 | N102: 0 | O102: 32 | P102: 12 | Q102: 12 | R102: 3 | S102: 4 | T102: 2 | U102: 2 | V102: 0 | W102: 0 | X102: 0 | Y102: 5 | Z102: 2 | AA102: 32 | AB102: 2 | AC102: 26 | AD102: 6 | AE102: 26

Sheet Project Information
A1: Project | B1: Rank | C1: Location | D1: NPD Feasibility | E1: Status
A2: 893 | B2: 1 | C2: SG | D2: Optimal | E2: Live
A3: 990 | B3: 2 | C3: PH | D3: Optimal | E3: Live | T3: Date:
A4: 923 | B4: 3 | C4: PH | D4: Optimal | E4: Live
A5: 946A | B5: 4 | C5: SG | D5: Optimal | E5: Live
A6: 922 | B6: 5 | C6: SG | D6: Optimal | E6: Live
A7: 308M | B7: 6 | C7: PH | D7: Optimal | E7: Live
A8: 873 | B8: 7 | C8: PH | D8: Sub Optimal | E8: Live
A9: 913 | B9: 8 | C9: SG | D9: Optimal | E9: Live
A10: 953 | B10: 9 | C10: PH | D10: Optimal | E10: Live
A11: 924 | B11: 10 | C11: PH | D11: Optimal | E11: Live
A12: 921A | B12: 11 | C12: PH | D12: Optimal | E12: Live
A13: 990A | B13: 12 | C13: PH | D13: Sub Optimal | E13: Scoping
A14: 980 | B14: 13 | C14: PH | D14: Sub Optimal | E14: Scoping
A15: 1027 | B15: 14 | C15: PH | D15: Sub Optimal | E15: Scoping
A16: 505N | B16: 15 | C16: PH | D16: Sub Optimal | E16: Scoping
A17: 1008 | B17: 16 | C17: PH | D17: Sub Optimal | E17: Scoping
A18: 982 | B18: 17 | C18: PH | D18: Sub Optimal | E18: Live
A19: 982A | B19: 18 | C19: PH | D19: Unsupported | E19: Scoping
A20: 1014 | B20: 19 | C20: PH | D20: Sub Optimal | E20: Scoping
A21: 1022 | B21: 20 | C21: PH | D21: Unsupported | E21: Scoping
A22: 1023 | B22: 21 | C22: PH | D22: Unsupported | E22: Scoping
A23: 982B | B23: 22 | C23: PH | D23: Unsupported | E23: Scoping
A24: 1005 | B24: 23 | C24: UK | D24: Unsupported | E24: Concept
A25: LX1391 | B25: 24 | C25: PH | D25: Sub Optimal | E25: Live
A26: LX1392 | B26: 25 | C26: PH | D26: Sub Optimal | E26: Scoping
A27: LX1274 | B27: 26 | D27: Sub Optimal | E27: Live

Sheet Project Milestone
A1: Project | B1: Milestone | C1: Cutoff Week | D1: Cutoff Year | E1: Cutoff Year
A2: 893 | B2: PVT4 | C2: 27 | D2: 2026 | E2: W27,26
A3: 990
A4: 923 | B4: DVT5 | C4: 20 | D4: 2026 | E4: W20,26
A5: 923 | B5: PVT4 | C5: 25 | D5: 2026 | E5: W25,26
A6: 946A | B6: ER | C6: 32 | D6: 2026 | E6: W32,26
A7: 922
A8: 308M
A9: 873 | B9: EVT1 | C9: 23 | D9: 2026 | E9: W23,26
A10: 873 | B10: EVT2 | C10: 25 | D10: 2026 | E10: W25,26
A11: 873 | B11: EVT3 | C11: 27 | D11: 2026 | E11: W27,26
A12: 873 | B12: EVT4 | C12: 29 | D12: 2026 | E12: W29,26
A13: 873 | B13: DVT1 | C13: 36 | D13: 2026 | E13: W36,26
A14: 873 | B14: DVT2 | C14: 38 | D14: 2026 | E14: W38,26
A15: 873 | B15: DVT3 | C15: 40 | D15: 2026 | E15: W40,26
A16: 873 | B16: DVT4 | C16: 42 | D16: 2026 | E16: W42,26
A17: 873 | B17: PVT1 | C17: 45 | D17: 2026 | E17: W45,26
A18: 873 | B18: PVT2 | C18: 47 | D18: 2026 | E18: W47,26
A19: 913 | B19: EVT1 | C19: 24 | D19: 2026 | E19: W24,26
A20: 913 | B20: DVT2 | C20: 29 | D20: 2026 | E20: W29,26
A21: 913 | B21: PVT1 | C21: 36 | D21: 2026 | E21: W36,26
A22: 953
A23: 924 | B23: PVT1 | C23: 23 | D23: 2026 | E23: W23,26
A24: 921A | B24: PVT1 | C24: 24 | D24: 2026 | E24: W24,26
A25: 990A
A26: 980
A27: 1027
A28: 505N
A29: 1008 | B29: Proto1 | C29: 39 | D29: 2026 | E29: W39,26
A30: 1008 | B30: EVT1 | C30: 51 | D30: 2026 | E30: W51,26
A31: 1008 | B31: DVT1 | C31: 11 | D31: 2027 | E31: W11,27
A32: 1008 | B32: PVT1 | C32: 21 | D32: 2027 | E32: W21, 27
A33: 982 | B33: DVT1 | C33: 36 | D33: 2026 | E33: W36,26
A34: 982 | B34: PVT1 | C34: 41 | D34: 2026 | E34: W41,26
A35: 982A | B35: Proto1 | C35: 30 | D35: 2026 | E35: W30,26
A36: 982A | B36: EVT1 | C36: 35 | D36: 2026 | E36: W35,26
A37: 982A | B37: DVT1 | C37: 20 | D37: 2026 | E37: W20,26
A38: 982A | B38: PVT1 | C38: 45 | D38: 2026 | E38: W45,26
A39: 1014
A40: 1022 | B40: DVT1 | C40: 33 | D40: 2026 | E40: W33,26
...

Sheet Capability
A1: TEST METHOD | B1: TEST NUMBER | C1: Lab Name | D1: Accessory | E1: Gifting | F1: Attachment | G1: Motors | H1: Device (Hair Straightener) | I1: Device (Hair Styler) | J1: Device (Hair Dryer) | K1: Device (Brush) | L1: Device (Curler) | M1: Device (Light Related Projects)
A2: Hair Styling Product - Retention Test | B2: TM-002725 | C2: HC Performance Lab (Styling) | D2: N | E2: N | F2: Y | G2: N | H2: N | I2: Y | J2: N | K2: Y | L2: N | M2: N
A3: Tress Imaging | B3: TM-003128 | C3: HC Performance Lab (Styling) | D3: N | E3: N | F3: Y | G3: N | H3: Y | I3: Y | J3: Y | K3: Y | L3: Y | M3: N
A4: Hair Binding Method | B4: TM-003034 | C4: HC Performance Lab | D4: N | E4: N | F4: N | G4: N | H4: N | I4: N | J4: N | K4: N | L4: N | M4: N
A5: User Course Test (Personal Care) | B5: TM-002643 | C5: User Interaction Lab | D5: Y | E5: Y | F5: Y | G5: Y | H5: Y | I5: Y | J5: Y | K5: Y | L5: Y | M5: Y
A6: Drop Test | B6: TM-003440 | C6: User Interaction Lab | D6: Y | E6: Y | F6: Y | G6: Y | H6: Y | I6: Y | J6: Y | K6: Y | L6: Y | M6: Y
A7: DTM 808 Free Loading Shipment Simulation Test | B7: TM-0000523 | C7: Robustness Lab | D7: Y | E7: Y | F7: Y | G7: Y | H7: Y | I7: Y | J7: Y | K7: Y | L7: Y | M7: Y
A8: DTM 712 - Materials - Chemical Resistance - Surface Application | B8: TM-0000458 | C8: User Interaction Lab | D8: Y | E8: Y | F8: Y | G8: N | H8: Y | I8: Y | J8: Y | K8: Y | L8: Y | M8: Y
A9: DTM040 Packaging Drop Test | B9: TM-0000028 | C9: Robustness Lab | D9: Y | E9: Y | F9: Y | G9: Y | H9: Y | I9: Y | J9: Y | K9: Y | L9: Y | M9: Y
A10: DTM 807 Palletized Shipment Simulation Test | B10: TM-0000516 | C10: Robustness Lab | D10: Y | E10: Y | F10: Y | G10: Y | H10: Y | I10: Y | J10: Y | K10: Y | L10: Y | M10: Y
A11: Accelerated Usage Life Test | B11: TM-200130 | C11: User Interaction Lab | D11: N | E11: N | F11: Y | G11: N | H11: Y | I11: Y | J11: N | K11: Y | L11: Y | M11: N
A12: Single Mode Life Lab Test | B12: TM-200124 | C12: Life Test Lab | D12: N | E12: N | F12: Y | G12: Y | H12: Y | I12: Y | J12: Y | K12: Y | L12: Y | M12: Y
... A94: Measurement of Centre of Mass in 2D plane | B94: TM-200307 | C94: HC Performance Lab | D94: N | E94: N | F94: N | G94: N | H94: N | I94: N | J94: N | K94: N | L94: N | M94: N

Sheet TM Demand Per Month (Life)
F7: Jan | G7: Feb | H7: Mar | I7: Apr | J7: May | K7: Jun | L7: Jul | M7: Aug | N7: Sep | O7: Oct | P7: Nov | Q7: Dec
C8: Technician | D8: TM-100590 | E8: Performance Life Test | F8: ='[2]Demand Per TM'!U242 -> 2428.8 | G8: ='[2]Demand Per TM'!V242 -> 3748.8 | H8: ='[2]Demand Per TM'!W242 -> 3722.4 | I8: ='[2]Demand Per TM'!X242 -> 2560.8 | J8: ='[2]Demand Per TM'!Y242 -> 1504.8 | K8: ='[2]Demand Per TM'!Z242 -> 1795.2 | L8: ='[2]Demand Per TM'!AA242 -> 3801.6 | M8: ='[2]Demand Per TM'!AB242 -> 3379.2 | ... Q8: ='[2]Demand Per TM'!AF242 -> 396
C9: Technician | D9: TM-200124 | E9: Single Mode Life Test | F9: ='[2]Demand Per TM'!U218 -> 844.8 | G9: ='[2]Demand Per TM'!V218 -> 2692.8 | H9: ='[2]Demand Per TM'!W218 -> 3062.4 | I9: ='[2]Demand Per TM'!X218 -> 2032.8 | J9: ='[2]Demand Per TM'!Y218 -> 712.8 | K9: ='[2]Demand Per TM'!Z218 -> 158.4 | L9: ='[2]Demand Per TM'!AA218 -> 1584 | M9: ='[2]Demand Per TM'!AB218 -> 1584 | ... Q9: ='[2]Demand Per TM'!AF218 -> 396

Sheet TM Demand Per Month (Robustness
E7: Location | F7: Jan | G7: Feb | H7: Mar | I7: Apr | J7: May | K7: Jun | L7: Jul | M7: Aug | N7: Sep | O7: Oct | P7: Nov | Q7: Dec
C8: TM-0000028 | D8: DTM040 Packaging Drop Test | E8: In House | F8: 0 | G8: 31 | H8: 31 | I8: 16 | J8: 62 | K8: 16 | L8: 0 | M8: 0 | N8: 62 | O8: 47 | P8: 78 | Q8: 78
C9: TM-0000028 | D9: DTM040 Packaging Drop Test | E9: JDM | F9: 0 | G9: 16 | H9: 31 | I9: 0 | J9: 0 | K9: 31 | L9: 78 | M9: 31 | N9: 93 | O9: 62 | P9: 47 | Q9: 31
C10: TM-003506 | D10: Mechanical Load Test | E10: In House | F10: 41 | G10: 243 | H10: 54 | I10: 27 | J10: 54 | K10: 0 | L10: 0 | M10: 0 | N10: 54 | O10: 0 | P10: 27 | Q10: 27
C11: TM-003506 | D11: Mechanical Load Test | E11: JDM | F11: 0 | G11: 20 | H11: 54 | I11: 0 | J11: 0 | K11: 14 | L11: 81 | M11: 61 | N11: 115 | O11: 162 | P11: 142 | Q11: 142
C12: TM-0000523 | D12: DTM 808 Free Loading Shipment Simulation Test | E12: In House | F12: 0 | G12: 73 | H12: 73 | I12: 36 | J12: 145 | K12: 36 | L12: 0 | M12: 0 | N12: 145 | O12: 109 | P12: 182 | Q12: 182
C13: TM-0000523 | D13: DTM 808 Free Loading Shipment Simulation Test | E13: JDM | F13: 0 | G13: 36 | H13: 73 | I13: 0 | J13: 0 | K13: 73 | L13: 182 | M13: 73 | N13: 218 | O13: 145 | P13: 109 | Q13: 73
C14: TM-003508 | D14: Hair Irons Full Product Mechanical Articulation Test (Hinge Life) | E14: In House | F14: 0 | G14: 99 | H14: 99 | I14: 126 | J14: 248 | K14: 27 | L14: 0 | M14: 0 | N14: 149 | O14: 0 | P14: 50 | Q14: 99
C15: TM-003508 | D15: Hair Irons Full Product Mechanical Articulation Test (Hinge Life) | E15: JDM | F15: 0 | G15: 0 | H15: 0 | I15: 0 | J15: 0 | K15: 0 | L15: 0 | M15: 0 | N15: 0 | O15: 0 | P15: 0 | Q15: 0
C16: TM-0000427 | D16: DTM 028 Cable Oscillation Test | E16: In House | F16: 0 | G16: 0 | H16: 0 | I16: 0 | J16: 851 | K16: 0 | L16: 0 | M16: 0 | N16: 851 | O16: 0 | P16: 425 | Q16: 425
C17: TM-0000427 | D17: DTM 028 Cable Oscillation Test | E17: JDM | F17: 0 | G17: 0 | H17: 851 | I17: 851 | J17: 0 | K17: 851 | L17: 851 | M17: 851 | N17: 0 | O17: 851 | P17: 0 | Q17: 0
C18: TM-002447 | D18: Washable Part Robustness Test | E18: In House | F18: 0 | G18: 0 | H18: 0 | I18: 0 | J18: 142 | K18: 0 | L18: 0 | M18: 0 | N18: 142 | O18: 0 | P18: 47 | Q18: 95
C19: TM-002447 | D19: Washable Part Robustness Test | E19: JDM | F19: 0 | G19: 47 | H19: 47 | I19: 0 | J19: 0 | K19: 47 | L19: 47 | M19: 47 | N19: 0 | O19: 47 | P19: 0 | Q19: 0
... C37: TM-003589 | D37: Moisture & Liquid Ingress for Personal Care | E37: JDM | F37: 0 | G37: 68 | H37: 68 | I37: 0 | J37: 0 | K37: 68 | L37: 135 | M37: 135 | N37: 0 | O37: 68 | P37: 0 | Q37: 0

Sheet TM Demand Per Month (Perf)
E7: Location | F7: Jan | G7: Feb | H7: Mar | I7: Apr | J7: May | K7: Jun | L7: Jul | M7: Aug | N7: Sep | O7: Oct | P7: Nov | Q7: Dec
C8: TM-0000777 | D8: DTM 912 Primary Air Flow Rate Test | E8: In House | F8: ='[2]Demand Per TM'!U277 -> 61.484625 | G8: ='[2]Demand Per TM'!V277 -> 59.985 | H8: ='[2]Demand Per TM'!W277 -> 17.9955 | I8: ='[2]Demand Per TM'!X277 -> 19.495125 | J8: ='[2]Demand Per TM'!Y277 -> 37.490625 | K8: ='[2]Demand Per TM'!Z277 -> 0 | L8: ='[2]Demand Per TM'!AA277 -> 13.496625 | M8: ='[2]Demand Per TM'!AB277 -> 0 | ... Q8: ='[2]Demand Per TM'!AF277 -> 10.664
C9: TM-0000777 | D9: DTM 912 Primary Air Flow Rate Test | E9: JDM | F9: ='[2]Demand Per TM'!U278 -> 0 | G9: ='[2]Demand Per TM'!V278 -> 5.9985 | H9: ='[2]Demand Per TM'!W278 -> 38.99025 | I9: ='[2]Demand Per TM'!X278 -> 13.496625 | J9: ='[2]Demand Per TM'!Y278 -> 0 | K9: ='[2]Demand Per TM'!Z278 -> 0 | L9: ='[2]Demand Per TM'!AA278 -> 53.9865 | M9: ='[2]Demand Per TM'!AB278 -> 26.99325 | ... Q9: ='[2]Demand Per TM'!AF278 -> 14.99625
C10: TM-005481 | D10: Real Hair Rough Dry Test Method | E10: In House | F10: ='[2]Demand Per TM'!U289 -> 18.266667 | G10: ='[2]Demand Per TM'!V289 -> 146.13333 | H10: ='[2]Demand Per TM'!W289 -> 0 | I10: ='[2]Demand Per TM'!X289 -> 73.066667 | J10: ='[2]Demand Per TM'!Y289 -> 0 | K10: ='[2]Demand Per TM'!Z289 -> 0 | L10: ='[2]Demand Per TM'!AA289 -> 73.066667 | M10: ='[2]Demand Per TM'!AB289 -> 0 | ... Q10: ='[2]Demand Per TM'!AF289 -> 0
C11: TM-005481 | D11: Real Hair Rough Dry Test Method | E11: JDM | F11: ='[2]Demand Per TM'!U290 -> 0 | G11: ='[2]Demand Per TM'!V290 -> 0 | H11: ='[2]Demand Per TM'!W290 -> 164.4 | I11: ='[2]Demand Per TM'!X290 -> 164.4 | J11: ='[2]Demand Per TM'!Y290 -> 0 | K11: ='[2]Demand Per TM'!Z290 -> 0 | L11: ='[2]Demand Per TM'!AA290 -> 92.475 | M11: ='[2]Demand Per TM'!AB290 -> 0 | ... Q11: ='[2]Demand Per TM'!AF290 -> 0
C12: TM-003732 | D12: Straightener Style and Dry Time Performance | E12: In House | F12: ='[2]Demand Per TM'!U308 -> 173.22525 | G12: ='[2]Demand Per TM'!V308 -> 46.1934 | H12: ='[2]Demand Per TM'!W308 -> 0 | I12: ='[2]Demand Per TM'!X308 -> 80.83845 | J12: ='[2]Demand Per TM'!Y308 -> 0 | K12: ='[2]Demand Per TM'!Z308 -> 0 | L12: ='[2]Demand Per TM'!AA308 -> 0 | M12: ='[2]Demand Per TM'!AB308 -> 0 | ... Q12: ='[2]Demand Per TM'!AF308 -> 0
C13: TM-003732 | D13: Straightener Style and Dry Time Performance | E13: JDM | F13: ='[2]Demand Per TM'!U309 -> 0 | G13: ='[2]Demand Per TM'!V309 -> 0 | H13: ='[2]Demand Per TM'!W309 -> 80.83845 | I13: ='[2]Demand Per TM'!X309 -> 0 | J13: ='[2]Demand Per TM'!Y309 -> 0 | K13: ='[2]Demand Per TM'!Z309 -> 80.83845 | L13: ='[2]Demand Per TM'!AA309 -> 300.2571 | M13: ='[2]Demand Per TM'!AB309 -> 0 | ... Q13: ='[2]Demand Per TM'!AF309 -> 138.5802
C14: TM-003666 | D14: Surface Temperature Mapping of PC Straightener Products | E14: In House | F14: ='[2]Demand Per TM'!U348 -> 46.95 | G14: ='[2]Demand Per TM'!V348 -> 281.7 | H14: ='[2]Demand Per TM'!W348 -> 93.9 | I14: ='[2]Demand Per TM'!X348 -> 46.95 | J14: ='[2]Demand Per TM'!Y348 -> 117.375 | K14: ='[2]Demand Per TM'!Z348 -> 0 | L14: ='[2]Demand Per TM'!AA348 -> 93.9 | M14: ='[2]Demand Per TM'!AB348 -> 0 | ... Q14: ='[2]Demand Per TM'!AF348 -> 62.6
C15: TM-003666 | D15: Surface Temperature Mapping of PC Straightener Products | E15: JDM | F15: ='[2]Demand Per TM'!U349 -> 0 | G15: ='[2]Demand Per TM'!V349 -> 46.95 | H15: ='[2]Demand Per TM'!W349 -> 352.125 | I15: ='[2]Demand Per TM'!X349 -> 140.85 | J15: ='[2]Demand Per TM'!Y349 -> 0 | K15: ='[2]Demand Per TM'!Z349 -> 46.95 | L15: ='[2]Demand Per TM'!AA349 -> 234.75 | M15: ='[2]Demand Per TM'!AB349 -> 187.8 | ... Q15: ='[2]Demand Per TM'!AF349 -> 93.9
C16: TM-003012 | D16: Wrap Performance Test Method | E16: In House | F16: ='[2]Demand Per TM'!U356 -> 0 | G16: ='[2]Demand Per TM'!V356 -> 5.2146429 | H16: ='[2]Demand Per TM'!W356 -> 0 | I16: ='[2]Demand Per TM'!X356 -> 0 | J16: ='[2]Demand Per TM'!Y356 -> 26.073214 | K16: ='[2]Demand Per TM'!Z356 -> 0 | L16: ='[2]Demand Per TM'!AA356 -> 0 | M16: ='[2]Demand Per TM'!AB356 -> 0 | ... Q16: ='[2]Demand Per TM'!AF356 -> 13.905714
C17: TM-003012 | D17: Wrap Performance Test Method | E17: JDM | F17: ='[2]Demand Per TM'!U357 -> 0 | G17: ='[2]Demand Per TM'!V357 -> 0 | H17: ='[2]Demand Per TM'!W357 -> 0 | I17: ='[2]Demand Per TM'!X357 -> 0 | J17: ='[2]Demand Per TM'!Y357 -> 0 | K17: ='[2]Demand Per TM'!Z357 -> 0 | L17: ='[2]Demand Per TM'!AA357 -> 0 | M17: ='[2]Demand Per TM'!AB357 -> 0 | ... Q17: ='[2]Demand Per TM'!AF357 -> 0

Sheet TM Demand Per Month (UI)
E7: Location | F7: Jan | G7: Feb | H7: Mar | I7: Apr | J7: May | K7: Jun | L7: Jul | M7: Aug | N7: Sep | O7: Oct | P7: Nov | Q7: Dec
C8: TM-002643 | D8: User Course Test (Personal Care) | E8: In House | F8: ='[2]Demand Per TM'!U36 -> 495 | G8: ='[2]Demand Per TM'!V36 -> 765 | H8: ='[2]Demand Per TM'!W36 -> 630 | I8: ='[2]Demand Per TM'!X36 -> 810 | J8: ='[2]Demand Per TM'!Y36 -> 810 | K8: ='[2]Demand Per TM'!Z36 -> 1350 | L8: ='[2]Demand Per TM'!AA36 -> 540 | M8: ='[2]Demand Per TM'!AB36 -> 945 | ... Q8: ='[2]Demand Per TM'!AF36 -> 675
C9: TM-002643 | D9: User Course Test (Personal Care) | E9: JDM | F9: ='[2]Demand Per TM'!U37 -> 0 | G9: ='[2]Demand Per TM'!V37 -> 135 | H9: ='[2]Demand Per TM'!W37 -> 0 | I9: ='[2]Demand Per TM'!X37 -> 135 | J9: ='[2]Demand Per TM'!Y37 -> 450 | K9: ='[2]Demand Per TM'!Z37 -> 990 | L9: ='[2]Demand Per TM'!AA37 -> 1350 | M9: ='[2]Demand Per TM'!AB37 -> 1440 | ... Q9: ='[2]Demand Per TM'!AF37 -> 2565
C10: TM-200181 | D10: Cosmetic Durability | E10: In House | F10: ='[2]Demand Per TM'!U51 -> 0 | G10: ='[2]Demand Per TM'!V51 -> 81 | H10: ='[2]Demand Per TM'!W51 -> 162 | I10: ='[2]Demand Per TM'!X51 -> 324 | J10: ='[2]Demand Per TM'!Y51 -> 27 | K10: ='[2]Demand Per TM'!Z51 -> 27 | L10: ='[2]Demand Per TM'!AA51 -> 27 | M10: ='[2]Demand Per TM'!AB51 -> 135 | ... Q10: ='[2]Demand Per TM'!AF51 -> 216
C11: TM-200181 | D11: Cosmetic Durability | E11: JDM | F11: ='[2]Demand Per TM'!U52 -> 0 | G11: ='[2]Demand Per TM'!V52 -> 0 | H11: ='[2]Demand Per TM'!W52 -> 0 | I11: ='[2]Demand Per TM'!X52 -> 0 | J11: ='[2]Demand Per TM'!Y52 -> 0 | K11: ='[2]Demand Per TM'!Z52 -> 27 | L11: ='[2]Demand Per TM'!AA52 -> 18 | M11: ='[2]Demand Per TM'!AB52 -> 0 | ... Q11: ='[2]Demand Per TM'!AF52 -> 0
C12: TM-200130 | D12: Accelerated Usage Life Test | E12: In House | F12: ='[2]Demand Per TM'!U79 -> 1980 | G12: ='[2]Demand Per TM'!V79 -> 2475 | H12: ='[2]Demand Per TM'!W79 -> 3960 | I12: ='[2]Demand Per TM'!X79 -> 6450 | J12: ='[2]Demand Per TM'!Y79 -> 6390 | K12: ='[2]Demand Per TM'!Z79 -> 3225 | L12: ='[2]Demand Per TM'!AA79 -> 495 | M12: ='[2]Demand Per TM'!AB79 -> 0 | ... Q12: ='[2]Demand Per TM'!AF79 -> 1980
C13: TM-200130 | D13: Accelerated Usage Life Test | E13: JDM | F13: ='[2]Demand Per TM'!U80 -> 0 | G13: ='[2]Demand Per TM'!V80 -> 495 | H13: ='[2]Demand Per TM'!W80 -> 495 | I13: ='[2]Demand Per TM'!X80 -> 720 | J13: ='[2]Demand Per TM'!Y80 -> 1605 | K13: ='[2]Demand Per TM'!Z80 -> 2970 | L13: ='[2]Demand Per TM'!AA80 -> 3960 | M13: ='[2]Demand Per TM'!AB80 -> 3645 | ... Q13: ='[2]Demand Per TM'!AF80 -> 3915
C14: TM-003440 | D14: Drop Test | E14: In House | F14: ='[2]Demand Per TM'!U114 -> 364.5 | G14: ='[2]Demand Per TM'!V114 -> 1458 | H14: ='[2]Demand Per TM'!W114 -> 567 | I14: ='[2]Demand Per TM'!X114 -> 405 | J14: ='[2]Demand Per TM'!Y114 -> 0 | K14: ='[2]Demand Per TM'!Z114 -> 0 | L14: ='[2]Demand Per TM'!AA114 -> 121.5 | M14: ='[2]Demand Per TM'!AB114 -> 243 | ... Q14: ='[2]Demand Per TM'!AF114 -> 243
C15: TM-003440 | D15: Drop Test | E15: JDM | F15: ='[2]Demand Per TM'!U115 -> 0 | G15: ='[2]Demand Per TM'!V115 -> 121.5 | H15: ='[2]Demand Per TM'!W115 -> 283.5 | I15: ='[2]Demand Per TM'!X115 -> 0 | J15: ='[2]Demand Per TM'!Y115 -> 0 | K15: ='[2]Demand Per TM'!Z115 -> 121.5 | L15: ='[2]Demand Per TM'!AA115 -> 486 | M15: ='[2]Demand Per TM'!AB115 -> 324 | ... Q15: ='[2]Demand Per TM'!AF115 -> 850.5
C16: TM-003706 | D16: Personal Long Hair Ingress | E16: In House | F16: ='[2]Demand Per TM'!U380 -> 27 | G16: ='[2]Demand Per TM'!V380 -> 81 | H16: ='[2]Demand Per TM'!W380 -> 13.5 | I16: ='[2]Demand Per TM'!X380 -> 40.5 | J16: ='[2]Demand Per TM'!Y380 -> 0 | K16: ='[2]Demand Per TM'!Z380 -> 0 | L16: ='[2]Demand Per TM'!AA380 -> 13.5 | M16: ='[2]Demand Per TM'!AB380 -> 13.5 | ... Q16: ='[2]Demand Per TM'!AF380 -> 13.5
C17: TM-003706 | D17: Personal Long Hair Ingress | E17: JDM | F17: ='[2]Demand Per TM'!U381 -> 0 | G17: ='[2]Demand Per TM'!V381 -> 13.5 | H17: ='[2]Demand Per TM'!W381 -> 13.5 | I17: ='[2]Demand Per TM'!X381 -> 0 | J17: ='[2]Demand Per TM'!Y381 -> 0 | K17: ='[2]Demand Per TM'!Z381 -> 13.5 | L17: ='[2]Demand Per TM'!AA381 -> 27 | M17: ='[2]Demand Per TM'!AB381 -> 27 | ... Q17: ='[2]Demand Per TM'!AF381 -> 0
C18: TM-002639 | D18: Cable Wrap Around Product Test | E18: In House | F18: ='[2]Demand Per TM'!U424 -> 0 | G18: ='[2]Demand Per TM'!V424 -> 0 | H18: ='[2]Demand Per TM'!W424 -> 0 | I18: ='[2]Demand Per TM'!X424 -> 202.5 | J18: ='[2]Demand Per TM'!Y424 -> 0 | K18: ='[2]Demand Per TM'!Z424 -> 0 | L18: ='[2]Demand Per TM'!AA424 -> 0 | M18: ='[2]Demand Per TM'!AB424 -> 0 | ... Q18: ='[2]Demand Per TM'!AF424 -> 202.5
C19: TM-002639 | D19: Cable Wrap Around Product Test | E19: JDM | F19: ='[2]Demand Per TM'!U425 -> 0 | G19: ='[2]Demand Per TM'!V425 -> 0 | H19: ='[2]Demand Per TM'!W425 -> 202.5 | I19: ='[2]Demand Per TM'!X425 -> 202.5 | J19: ='[2]Demand Per TM'!Y425 -> 0 | K19: ='[2]Demand Per TM'!Z425 -> 202.5 | L19: ='[2]Demand Per TM'!AA425 -> 202.5 | M19: ='[2]Demand Per TM'!AB425 -> 202.5 | ... Q19: ='[2]Demand Per TM'!AF425 -> 0
C20: TM-0000618 | D20: DTM 902 Tampo Durability Test | E20: In House | F20: ='[2]Demand Per TM'!U441 -> 0 | G20: ='[2]Demand Per TM'!V441 -> 20.25 | H20: ='[2]Demand Per TM'!W441 -> 33.75 | I20: ='[2]Demand Per TM'!X441 -> 40.5 | J20: ='[2]Demand Per TM'!Y441 -> 0 | K20: ='[2]Demand Per TM'!Z441 -> 0 | L20: ='[2]Demand Per TM'!AA441 -> 0 | M20: ='[2]Demand Per TM'!AB441 -> 40.5 | ... Q20: ='[2]Demand Per TM'!AF441 -> 40.5
C21: TM-0000618 | D21: DTM 902 Tampo Durability Test | E21: JDM | F21: ='[2]Demand Per TM'!U442 -> 0 | G21: ='[2]Demand Per TM'!V442 -> 20.25 | H21: ='[2]Demand Per TM'!W442 -> 47.25 | I21: ='[2]Demand Per TM'!X442 -> 0 | J21: ='[2]Demand Per TM'!Y442 -> 0 | K21: ='[2]Demand Per TM'!Z442 -> 20.25 | L21: ='[2]Demand Per TM'!AA442 -> 27 | M21: ='[2]Demand Per TM'!AB442 -> 27 | ... Q21: ='[2]Demand Per TM'!AF442 -> 0
C22: TM-0000674 | D22: DTM 900 Cordset Pull Out Test | E22: In House | F22: ='[2]Demand Per TM'!U489 -> 0 | G22: ='[2]Demand Per TM'!V489 -> 0 | H22: ='[2]Demand Per TM'!W489 -> 0 | I22: ='[2]Demand Per TM'!X489 -> 6.75 | J22: ='[2]Demand Per TM'!Y489 -> 0 | K22: ='[2]Demand Per TM'!Z489 -> 0 | L22: ='[2]Demand Per TM'!AA489 -> 0 | M22: ='[2]Demand Per TM'!AB489 -> 6.75 | ... Q22: ='[2]Demand Per TM'!AF489 -> 6.75
C23: TM-0000674 | D23: DTM 900 Cordset Pull Out Test | E23: JDM | F23: ='[2]Demand Per TM'!U490 -> 0 | G23: ='[2]Demand Per TM'!V490 -> 0 | H23: ='[2]Demand Per TM'!W490 -> 6.75 | I23: ='[2]Demand Per TM'!X490 -> 6.75 | J23: ='[2]Demand Per TM'!Y490 -> 0 | K23: ='[2]Demand Per TM'!Z490 -> 6.75 | L23: ='[2]Demand Per TM'!AA490 -> 6.75 | M23: ='[2]Demand Per TM'!AB490 -> 6.75 | ... Q23: ='[2]Demand Per TM'!AF490 -> 0
C24: TM-0000539 | D24: DTM815 Physical Resistance Test | E24: In House | F24: ='[2]Demand Per TM'!U459 -> 0 | G24: ='[2]Demand Per TM'!V459 -> 0 | H24: ='[2]Demand Per TM'!W459 -> 81 | I24: ='[2]Demand Per TM'!X459 -> 141.75 | J24: ='[2]Demand Per TM'!Y459 -> 0 | K24: ='[2]Demand Per TM'!Z459 -> 0 | L24: ='[2]Demand Per TM'!AA459 -> 0 | M24: ='[2]Demand Per TM'!AB459 -> 60.75 | ... Q24: ='[2]Demand Per TM'!AF459 -> 121.5
C25: TM-0000539 | D25: DTM815 Physical Resistance Test | E25: JDM | F25: ='[2]Demand Per TM'!U460 -> 0 | G25: ='[2]Demand Per TM'!V460 -> 13.5 | H25: ='[2]Demand Per TM'!W460 -> 27 | I25: ='[2]Demand Per TM'!X460 -> 0 | J25: ='[2]Demand Per TM'!Y460 -> 0 | K25: ='[2]Demand Per TM'!Z460 -> 13.5 | L25: ='[2]Demand Per TM'!AA460 -> 27 | M25: ='[2]Demand Per TM'!AB460 -> 27 | ... Q25: ='[2]Demand Per TM'!AF460 -> 0
C26: TM-0000458 | D26: DTM 712 - Materials - Chemical Resistance - Surface Application | E26: In House | F26: ='[2]Demand Per TM'!U477 -> 0 | G26: ='[2]Demand Per TM'!V477 -> 0 | H26: ='[2]Demand Per TM'!W477 -> 810 | I26: ='[2]Demand Per TM'!X477 -> 1113.75 | J26: ='[2]Demand Per TM'!Y477 -> 0 | K26: ='[2]Demand Per TM'!Z477 -> 0 | L26: ='[2]Demand Per TM'!AA477 -> 0 | M26: ='[2]Demand Per TM'!AB477 -> 303.75 | ... Q26: ='[2]Demand Per TM'!AF477 -> 911.25
C27: TM-0000458 | D27: DTM 712 - Materials - Chemical Resistance - Surface Application | E27: JDM | F27: ='[2]Demand Per TM'!U478 -> 0 | G27: ='[2]Demand Per TM'!V478 -> 67.5 | H27: ='[2]Demand Per TM'!W478 -> 135 | I27: ='[2]Demand Per TM'!X478 -> 0 | J27: ='[2]Demand Per TM'!Y478 -> 0 | K27: ='[2]Demand Per TM'!Z478 -> 67.5 | L27: ='[2]Demand Per TM'!AA478 -> 135 | M27: ='[2]Demand Per TM'!AB478 -> 135 | ... Q27: ='[2]Demand Per TM'!AF478 -> 0

Sheet 893
A2: Category | B2: Test Method | C2: Test Number | D2: Proto1 | E2: Date (Week) | F2: Date (Day) | G2: DVT1 | H2: Date (Week) | I2: Date (Day) | J2: EVT1 | K2: Date (Week) | L2: Date (Day) | M2: PVT1 | N2: Date (Week) | O2: Date (Day) | P2: Other | Q2: Date (Week) | R2: Date (Day) | S2: Other | T2: Date (Week) | U2: Date (Day) | V2: Other | W2: Date (Week) | X2: Date (Day) | Y2: Other | Z2: Date (Week) | AA2: Date (Day) | AB2: Other | AC2: Date (Week) | AD2: Date (Day) | AE2: Other | AF2: Date (Week) | AG2: Date (Day) | AH2: Other | AI2: Date (Week) | AJ2: Date (Day)
A3: Device (Hair Dryer) | B3: Tress Imaging | C3: TM-003128 | D3: 15 | E3: 11 | F3: 2 | G3: 15 | H3: 13 | I3: 10 | J3: 15 | K3: 15 | L3: 15 | M3: 15 | N3: 20 | O3: 2
A4: Device (Hair Dryer) | B4: User Course Test (Personal Care) | C4: TM-002643 | D4: 15 | E4: 11 | F4: 2 | G4: 15 | H4: 13 | I4: 10 | J4: 15 | K4: 15 | L4: 15 | M4: 15 | N4: 20 | O4: 2
A5: Device (Hair Dryer) | B5: Drop Test | C5: TM-003440 | D5: 15 | E5: 11 | F5: 2 | G5: 15 | H5: 13 | I5: 10 | J5: 15 | K5: 15 | L5: 15 | M5: 15 | N5: 20 | O5: 2
A6: Device (Hair Dryer) | B6: DTM 808 Free Loading Shipment Simulation Test | C6: TM-0000523 | D6: 15 | E6: 11 | F6: 2 | G6: 15 | H6: 13 | I6: 10 | J6: 15 | K6: 15 | L6: 15 | M6: 15 | N6: 20 | O6: 2
A7: Device (Hair Dryer) | B7: DTM 712 - Materials - Chemical Resistance - Surface Application | C7: TM-0000458 | D7: 15 | E7: 11 | F7: 2 | G7: 15 | H7: 13 | I7: 10 | J7: 15 | K7: 15 | L7: 15 | M7: 15 | N7: 20 | O7: 2
A8: Device (Hair Dryer) | B8: DTM040 Packaging Drop Test | C8: TM-0000028 | D8: 15 | E8: 11 | F8: 2 | G8: 15 | H8: 13 | I8: 10 | J8: 15 | K8: 15 | L8: 15 | M8: 15 | N8: 20 | O8: 2
A9: Device (Hair Dryer) | B9: DTM 807 Palletized Shipment Simulation Test | C9: TM-0000516 | D9: 15 | E9: 11 | F9: 2 | G9: 15 | H9: 13 | I9: 10 | J9: 15 | K9: 15 | L9: 15 | M9: 15 | N9: 20 | O9: 2
A10: Device (Hair Dryer) | B10: Single Mode Life Lab Test | C10: TM-200124 | D10: 15 | E10: 11 | F10: 2 | G10: 15 | H10: 13 | I10: 10 | J10: 15 | K10: 15 | L10: 15 | M10: 15 | N10: 20 | O10: 2
A11: Device (Hair Dryer) | B11: Mechanical Load Test | C11: TM-003506 | D11: 15 | E11: 11 | F11: 2 | G11: 15 | H11: 13 | I11: 10 | J11: 15 | K11: 15 | L11: 15 | M11: 15 | N11: 20 | O11: 2
A12: Device (Hair Dryer) | B12: Cosmetic Durability | C12: TM-200181 | D12: 15 | E12: 11 | F12: 2 | G12: 15 | H12: 13 | I12: 10 | J12: 15 | K12: 15 | L12: 15 | M12: 15 | N12: 20 | O12: 2
A13: Device (Hair Dryer) | B13: DTM 533 Removable Parts, clips and catches | C13: TM-0000426 | D13: 15 | E13: 11 | F13: 2 | G13: 15 | H13: 13 | I13: 10 | J13: 15 | K13: 15 | L13: 15 | M13: 15 | N13: 20 | O13: 2
A14: Device (Hair Dryer) | B14: DTM 902 Tampo Durability Test | C14: TM-0000618 | D14: 15 | E14: 11 | F14: 2 | G14: 15 | H14: 13 | I14: 10 | J14: 15 | K14: 15 | L14: 15 | M14: 15 | N14: 20 | O14: 2
... A87: Accessory | B87: Thermal Cycling Storage Test | C87: TM-0000591 | D87: 10 | E87: 10 | F87: 4 | G87: 5 | H87: 14 | I87: 2 | J87: 20 | K87: 20 | L87: 7 | M87: 10 | N87: 18 | O87: 3
A90: Gifting | B90: {=IF($A90="","",_xlfn._xlws.FILTER(Capability!A2:A200,INDEX(Capability!D2:Z200,,MATCH($A90,Capability!D1:Z1,0))="Y"))} -> User Course Test (Personal Care) | C90: {=IF(_xlfn.ANCHORARRAY(B90)="","",_xlfn._xlws.FILTER(Capability!B2:B200,INDEX(Capability!D2:Z200,,MATCH($A90,Capability!D1:Z1,0))="Y"))} -> TM-002643 | D90: 10 | E90: 10 | F90: 4 | G90: 5 | H90: 14 | I90: 2 | J90: 20 | K90: 20 | L90: 7 | M90: 10 | N90: 18 | O90: 3
A91: Gifting | B91: Drop Test | C91: TM-003440 | D91: 10 | E91: 10 | F91: 4 | G91: 5 | H91: 14 | I91: 2 | J91: 20 | K91: 20 | L91: 7 | M91: 10 | N91: 18 | O91: 3
A92: Gifting | B92: DTM 808 Free Loading Shipment Simulation Test | C92: TM-0000523 | D92: 10 | E92: 10 | F92: 4 | G92: 5 | H92: 14 | I92: 2 | J92: 20 | K92: 20 | L92: 7 | M92: 10 | N92: 18 | O92: 3
A93: Gifting | B93: DTM 712 - Materials - Chemical Resistance - Surface Application | C93: TM-0000458 | D93: 10 | E93: 10 | F93: 4 | G93: 5 | H93: 14 | I93: 2 | J93: 20 | K93: 20 | L93: 7 | M93: 10 | N93: 18 | O93: 3
A94: Gifting | B94: DTM040 Packaging Drop Test | C94: TM-0000028 | D94: 10 | E94: 10 | F94: 4 | G94: 5 | H94: 14 | I94: 2 | J94: 20 | K94: 20 | L94: 7 | M94: 10 | N94: 18 | O94: 3
A95: Gifting | B95: DTM 807 Palletized Shipment Simulation Test | C95: TM-0000516 | D95: 10 | E95: 10 | F95: 4 | G95: 5 | H95: 14 | I95: 2 | J95: 20 | K95: 20 | L95: 7 | M95: 10 | N95: 18 | O95: 3
A96: Gifting | B96: Cosmetic Durability | C96: TM-200181 | D96: 10 | E96: 10 | F96: 4 | G96: 5 | H96: 14 | I96: 2 | J96: 20 | K96: 20 | L96: 7 | M96: 10 | N96: 18 | O96: 3
A97: Gifting | B97: DTM 902 Tampo Durability Test | C97: TM-0000618 | D97: 10 | E97: 10 | F97: 4 | G97: 5 | H97: 14 | I97: 2 | J97: 20 | K97: 20 | L97: 7 | M97: 10 | N97: 18 | O97: 3
A98: Gifting | B98: DTM815 Physical Resistance Test | C98: TM-0000539 | D98: 10 | E98: 10 | F98: 4 | G98: 5 | H98: 14 | I98: 2 | J98: 20 | K98: 20 | L98: 7 | M98: 10 | N98: 18 | O98: 3
A99: Gifting | B99: ISTA 3A: Packaged | C99: TM-0000880 | D99: 10 | E99: 10 | F99: 4 | G99: 5 | H99: 14 | I99: 2 | J99: 20 | K99: 20 | L99: 7 | M99: 10 | N99: 18 | O99: 3
A100: Gifting | B100: DTM332 Random, Low Shock, Sweep and High Shock Vibration Test | C100: TM-0000372 | D100: 10 | E100: 10 | F100: 4 | G100: 5 | H100: 14 | I100: 2 | J100: 20 | K100: 20 | L100: 7 | M100: 10 | N100: 18 | O100: 3
A104: Attachment | B104: {=IF($A104="","",_xlfn._xlws.FILTER(Capability!A2:A200,INDEX(Capability!D2:Z200,,MATCH($A104,Capability!D1:Z1,0))="Y"))} -> Hair Styling Product - Retention Test | C104: {=IF(_xlfn.ANCHORARRAY(B104)="","",_xlfn._xlws.FILTER(Capability!B2:B200,INDEX(Capability!D2:Z200,,MATCH($A104,Capability!D1:Z1,0))="Y"))} -> TM-002725 | D104: 10 | E104: 10 | F104: 4 | G104: 5 | H104: 14 | I104: 2 | J104: 20 | K104: 20 | L104: 7 | M104: 10 | N104: 18 | O104: 3
A105: Attachment | B105: Tress Imaging | C105: TM-003128 | D105: 15 | E105: 11 | F105: 2 | G105: 15 | H105: 13 | I105: 10 | J105: 15 | K105: 15 | L105: 15 | M105: 15 | N105: 20 | O105: 2
A106: Attachment | B106: User Course Test (Personal Care) | C106: TM-002643 | D106: 15 | E106: 11 | F106: 2 | G106: 15 | H106: 13 | I106: 10 | J106: 15 | K106: 15 | L106: 15 | M106: 15 | N106: 20 | O106: 2
A107: Attachment | B107: Drop Test | C107: TM-003440 | D107: 15 | E107: 11 | F107: 2 | G107: 15 | H107: 13 | I107: 10 | J107: 15 | K107: 15 | L107: 15 | M107: 15 | N107: 20 | O107: 2
A108: Attachment | B108: DTM 808 Free Loading Shipment Simulation Test | C108: TM-0000523 | D108: 15 | E108: 11 | F108: 2 | G108: 15 | H108: 13 | I108: 10 | J108: 15 | K108: 15 | L108: 15 | M108: 15 | N108: 20 | O108: 2
A109: Attachment | B109: DTM 712 - Materials - Chemical Resistance - Surface Application | C109: TM-0000458 | D109: 15 | E109: 11 | F109: 2 | G109: 15 | H109: 13 | I109: 10 | J109: 15 | K109: 15 | L109: 15 | M109: 15 | N109: 20 | O109: 2
A110: Attachment | B110: DTM040 Packaging Drop Test | C110: TM-0000028 | D110: 15 | E110: 11 | F110: 2 | G110: 15 | H110: 13 | I110: 10 | J110: 15 | K110: 15 | L110: 15 | M110: 15 | N110: 20 | O110: 2
A111: Attachment | B111: DTM 807 Palletized Shipment Simulation Test | C111: TM-0000516 | D111: 15 | E111: 11 | F111: 2 | G111: 15 | H111: 13 | I111: 10 | J111: 15 | K111: 15 | L111: 15 | M111: 15 | N111: 20 | O111: 2
A112: Attachment | B112: Accelerated Usage Life Test | C112: TM-200130 | D112: 15 | E112: 11 | F112: 2 | G112: 15 | H112: 13 | I112: 10 | J112: 15 | K112: 15 | L112: 15 | M112: 15 | N112: 20 | O112: 2
A113: Attachment | B113: Single Mode Life Lab Test | C113: TM-200124 | D113: 15 | E113: 11 | F113: 2 | G113: 15 | H113: 13 | I113: 10 | J113: 15 | K113: 15 | L113: 15 | M113: 15 | N113: 20 | O113: 2
A114: Attachment | B114: Mechanical Load Test | C114: TM-003506 | D114: 15 | E114: 11 | F114: 2 | G114: 15 | H114: 13 | I114: 10 | J114: 15 | K114: 15 | L114: 15 | M114: 15 | N114: 20 | O114: 2
A115: Attachment | B115: Cosmetic Durability | C115: TM-200181 | D115: 15 | E115: 11 | F115: 2 | G115: 15 | H115: 13 | I115: 10 | J115: 15 | K115: 15 | L115: 15 | M115: 15 | N115: 20 | O115: 2
A116: Attachment | B116: DTM 533 Removable Parts, clips and catches | C116: TM-0000426 | D116: 15 | E116: 11 | F116: 2 | G116: 15 | H116: 13 | I116: 10 | J116: 15 | K116: 15 | L116: 15 | M116: 15 | N116: 20 | O116: 2
... A150: Attachment | B150: Personal Care Product Environmental Test | C150: TM-002644 | D150: 15 | E150: 11 | F150: 2 | G150: 15 | H150: 13 | I150: 10 | J150: 15 | K150: 15 | L150: 15 | M150: 15 | N150: 20 | O150: 2
A154: Motors | B154: {=IF($A154="","",_xlfn._xlws.FILTER(Capability!A2:A200,INDEX(Capability!D2:Z200,,MATCH($A154,Capability!D1:Z1,0))="Y"))} -> User Course Test (Personal Care) | C154: {=IF(_xlfn.ANCHORARRAY(B154)="","",_xlfn._xlws.FILTER(Capability!B2:B200,INDEX(Capability!D2:Z200,,MATCH($A154,Capability!D1:Z1,0))="Y"))} -> TM-002643 | D154: 15 | E154: 11 | F154: 2 | G154: 15 | H154: 13 | I154: 10 | J154: 15 | K154: 15 | L154: 15 | M154: 15 | N154: 20 | O154: 2
...

Sheet 990
